Workbook

Sheet Lisez-moi
A1: Fondamentaux Grasshopper – Référentiel des notions Magpie | D1: Fondamentaux Grasshopper – Ind. A – 25/08/2026
A3: Projet | B3: MAGPIE – outil d'exercices Grasshopper autocorrigés (RhinoForYou)
A4: Objet du document | B4: Référentiel unique des notions Rhino / Grasshopper à couvrir par les exercices Magpie, obtenu en fusionnant le tableau des fondamentaux V1 et l'intégralité du contenu des programmes de formation du catalogue.
A5: Indice | B5: Ind. A
A6: Date | B6: 25/08/2026
A7: Établi par | B7: Charles THIERRY DE VILLE D'AVRAY
A8: Document source remplacé | B8: Fondamentaux Grasshopper.xlsx (19 notions, 6 familles) – conservé sans modification
A9: Action de référence | B9: Compte rendu de session du 11/08/2026, §5.1 et §9.2 : « Comparer le tableau des fondamentaux aux programmes RhinoForYou débutant et perfectionnement ».
A11: SOURCES DÉPOUILLÉES
A12: D3 | B12: Grasshopper débutant 3 jours — Programme de formation Grasshopper débutant 3 jours.docx
A13: P3 | B13: Grasshopper perfectionnement 3 jours — Programme de formation Grasshopper perfectionnement 3 jours.docx
A14: P6 | B14: Grasshopper perfectionnement 6 jours — Programme de formation Grasshopper perfectionnement 6 jours.docx
A15: P6b | B15: Grasshopper perfectionnement 6 jours (1) — Programme de formation Grasshopper perfectionnement 6 jours (1).docx
A16: P6A | B16: Grasshopper perfectionnement 6 jours – Ind A – 27/02/2025 — Programme de formation Grasshopper perfectionnement 6 jours - IndA - 27-02-2025.docx
A17: RG8 | B17: Rhino – Grasshopper 8 jours — Programme de formation Grasshopper 8 jours.docx
A19: CONTENU DU CLASSEUR
A20: Référentiel | B20: Feuille principale. 116 lignes : 97 notions issues des programmes de formation + 19 fondamentaux Magpie V1, classés par domaine puis par catégorie.
A21: Fondamentaux V1 | B21: Reprise à l'identique du tableau d'origine (19 notions), pour traçabilité.
A22: Contenu programmes | B22: Relevé exhaustif et verbatim des 234 items des 6 programmes, dans l'ordre des documents, rattachés à une ligne du référentiel.
A23: Synthèse | B23: Comptages par domaine, niveau, mode de validation et programme ; analyse des écarts.
A24: Listes | B24: Listes de valeurs utilisées par les menus déroulants du référentiel.
A26: MÉTHODE
A27: 1 | B27: Extraction automatique de tous les paragraphes de liste des 6 programmes (234 occurrences).
A28: 2 | B28: Dédoublonnage par texte normalisé : 97 items distincts.
A29: 3 | B29: Classement de chaque item dans un domaine (10) et une catégorie, avec niveau et mode de validation proposés.
A30: 4 | B30: Intégration des 19 fondamentaux V1 et qualification de leur couverture par les programmes.
A31: 5 | B31: Construction de la matrice de couverture (une colonne par programme, valeur = jour · session).
A33: LÉGENDE — MODE DE VALIDATION
A34: ExactOrderedList | B34: Ordre des éléments significatif.
A35: SetEquality | B35: Ordre indifférent, ensemble attendu.
A36: SingleValue | B36: Une valeur unique attendue.
A37: NumericTolerance | B37: Valeur numérique avec marge d'erreur.
A38: GeometryTolerance | B38: Comparaison géométrique avec tolérance.
A39: Conceptuel (QCM) | B39: Notion non vérifiable par comparaison de résultat : question ciblée.
A41: LÉGENDE — ORIGINE
A42: Programme de formation | B42: Item présent dans au moins un programme du catalogue.
A43: Fondamentaux V1 – couverte | B43: Notion V1 explicitement traitée par un item de programme.
A44: Fondamentaux V1 – partielle | B44: Notion V1 incluse dans un item de programme plus large.
A45: Fondamentaux V1 – hors programmes | B45: Notion V1 absente des programmes : à arbitrer (ajout au programme ou exercice Magpie seul).
A47: POINTS À ARBITRER
...

Sheet Référentiel
A1: Référentiel des notions – Rhino / Grasshopper | Y1: Fondamentaux Grasshopper – Ind. A – 25/08/2026
A3: N° | B3: ID | C3: Domaine | D3: Catégorie | E3: Notion | F3: Libellé source / description | G3: Niveau | H3: Origine / couverture | I3: D3 3 j débutant | J3: P3 3 j perf. | K3: P6 6 j perf. | L3: P6b 6 j perf. (1) | M3: P6A 6 j perf. Ind A | N3: RG8 8 j Rhino+GH | O3: Nb prog. | P3: Ordre V1 | Q3: Réf. croisée | R3: ValidationMode suggéré | S3: Type d'exercice | T3: Priorité de production | U3: Nb exercices Magpie prévus | V3: À réaliser par | W3: Statut | X3: Lien | Y3: Notes
A4: 1 | B4: PRG-074 | C4: 0 – Socle Rhino (prérequis) | D4: Interface et navigation Rhino | E4: Interface Rhino | F4: Présentation de l'interface utilisateur (barres d’outils, fenêtres, options). | G4: Débutant | H4: Programme de formation | N4: J1 | O4: 1 | R4: Conceptuel (QCM) | S4: QCM / question ciblée | T4: P0
A5: 2 | B5: PRG-075 | C5: 0 – Socle Rhino (prérequis) | D5: Interface et navigation Rhino | E5: Manipulation des vues | F5: Manipulation des vues | G5: Débutant | H5: Programme de formation | N5: J1 | O5: 1 | R5: Conceptuel (QCM) | S5: QCM / question ciblée | T5: P0
A6: 3 | B6: PRG-076 | C6: 0 – Socle Rhino (prérequis) | D6: Interface et navigation Rhino | E6: Navigation | F6: Outils de navigation : zoom, panoramique, rotation. | G6: Débutant | H6: Programme de formation | N6: J1 | O6: 1 | R6: Conceptuel (QCM) | S6: QCM / question ciblée | T6: P0
A7: 4 | B7: PRG-079 | C7: 0 – Socle Rhino (prérequis) | D7: Interface et navigation Rhino | E7: Sélection d'objets | F7: Sélection et manipulation d’objets | G7: Débutant | H7: Programme de formation | N7: J1 | O7: 1 | R7: Conceptuel (QCM) | S7: QCM / question ciblée | T7: P0
A8: 5 | B8: PRG-080 | C8: 0 – Socle Rhino (prérequis) | D8: Interface et navigation Rhino | E8: Groupes et blocs | F8: Groupes et blocs | G8: Débutant | H8: Programme de formation | N8: J1 | O8: 1 | R8: Conceptuel (QCM) | S8: QCM / question ciblée | T8: P0
A9: 6 | B9: PRG-081 | C9: 0 – Socle Rhino (prérequis) | D9: Interface et navigation Rhino | E9: Visibilité des objets | F9: Verrouillage et masquage d’objets, Isoler, Montrer) | G9: Débutant | H9: Programme de formation | N9: J1 | O9: 1 | R9: Conceptuel (QCM) | S9: QCM / question ciblée | T9: P0
A10: 7 | B10: PRG-077 | C10: 0 – Socle Rhino (prérequis) | D10: Modélisation Rhino | E10: Objets de base | F10: Création et manipulation d'objets de base (cubes, sphères, cylindres, etc.). | G10: Débutant | H10: Programme de formation | N10: J1 | O10: 1 | R10: GeometryTolerance | S10: Exercice Grasshopper | T10: P0
A11: 8 | B11: PRG-078 | C11: 0 – Socle Rhino (prérequis) | D11: Modélisation Rhino | E11: Transformations de base | F11: Transformation de base : déplacer, tourner, échelle, orienter | G11: Débutant | H11: Programme de formation | N11: J1 | O11: 1 | R11: GeometryTolerance | S11: Exercice Grasshopper | T11: P0
A12: 9 | B12: PRG-082 | C12: 0 – Socle Rhino (prérequis) | D12: Modélisation Rhino | E12: Courbes Rhino | F12: Création de courbes de différentes formes (lignes, cercles, ellipses, etc.). | G12: Débutant | H12: Programme de formation | N12: J1 | O12: 1 | R12: GeometryTolerance | S12: Exercice Grasshopper | T12: P0
A13: 10 | B13: PRG-083 | C13: 0 – Socle Rhino (prérequis) | D13: Modélisation Rhino | E13: Surfaces depuis courbes | F13: Utilisation de l’outil de courbes pour générer des surfaces. | G13: Débutant | H13: Programme de formation | N13: J1 | O13: 1 | R13: GeometryTolerance | S13: Exercice Grasshopper | T13: P0
A14: 11 | B14: PRG-084 | C14: 0 – Socle Rhino (prérequis) | D14: Modélisation Rhino | E14: Extrusion | F14: Extrusion et création de surfaces à partir de courbes. | G14: Débutant | H14: Programme de formation | N14: J1 | O14: 1 | R14: GeometryTolerance | S14: Exercice Grasshopper | T14: P0
A15: 12 | B15: PRG-085 | C15: 0 – Socle Rhino (prérequis) | D15: Modélisation Rhino | E15: Opérations booléennes Rhino | F15: Opérations booléennes (Union, intersection, et soustraction) | G15: Débutant | H15: Programme de formation | N15: J1 | O15: 1 | R15: GeometryTolerance | S15: Exercice Grasshopper | T15: P0
... A27: 24 | B27: PRG-097 | C27: 0 – Socle Rhino (prérequis) | D27: Préparation à l'impression 3D | E27: Export STL / OBJ | F27: Exportation des modèles 3D au format STL ou OBJ et paramètres d'exportation et optimisation des maillages pour réduire les erreurs d’impression. | G27: Débutant | H27: Programme de formation | N27: J2 | O27: 1 | R27: Conceptuel (QCM) | S27: Démonstration formateur | T27: P0
A28: 25 | B28: PRG-001 | C28: 1 – Environnement et principes Grasshopper | D28: Principes et interface Grasshopper | E28: Principes de la conception paramétrique | F28: Introduction à la conception paramétrique avec Grasshopper (Principes de la programmation visuelle) | G28: Débutant | H28: Programme de formation | I28: J1 | N28: J3 | O28: 2 | R28: Conceptuel (QCM) | S28: QCM / question ciblée | T28: P0
A29: 26 | B29: PRG-002 | C29: 1 – Environnement et principes Grasshopper | D29: Principes et interface Grasshopper | E29: Interopérabilité Rhino – Grasshopper | F29: Interopérabilité entre Grasshopper et Rhino (Bake et Geometry Pipeline) | G29: Débutant | H29: Programme de formation | I29: J1 | N29: J3 | O29: 2 | R29: GeometryTolerance | S29: Exercice Grasshopper | T29: P0
A30: 27 | B30: PRG-003 | C30: 1 – Environnement et principes Grasshopper | D30: Principes et interface Grasshopper | E30: Flux de données et câblage | F30: La logique de Grasshopper (Curseurs, données d’entrée, panel, données de sortie, branchement des câbles… ) | G30: Débutant | H30: Programme de formation | I30: J1 | N30: J3 | O30: 2 | R30: SingleValue | S30: Exercice Grasshopper | T30: P0
A31: 28 | B31: PRG-004 | C31: 1 – Environnement et principes Grasshopper | D31: Principes et interface Grasshopper | E31: Interface et canvas | F31: L’environnement et l’interface de Grasshopper (Barre d’outils et navigation dans le Canvas) | G31: Débutant | H31: Programme de formation | I31: J1 | N31: J3 | O31: 2 | R31: Conceptuel (QCM) | S31: QCM / question ciblée | T31: P0
A32: 29 | B32: PRG-063 | C32: 1 – Environnement et principes Grasshopper | D32: Écosystème de plugins | E32: Installation de plugins – Food4Rhino | F32: Installer un plugin à partir d’un fichier gha ou exe téléchargé sur food4rhino | G32: Intermédiaire | H32: Programme de formation | M32: J2·S3 | O32: 1 | R32: Conceptuel (QCM) | S32: Démonstration formateur | T32: P1
A33: 30 | B33: PRG-064 | C33: 1 – Environnement et principes Grasshopper | D33: Écosystème de plugins | E33: Installation de plugins – Package Manager | F33: Installer un plugin depuis le package manager | G33: Intermédiaire | H33: Programme de formation | M33: J2·S3 | O33: 1 | R33: Conceptuel (QCM) | S33: Démonstration formateur | T33: P1
A34: 31 | B34: PRG-065 | C34: 1 – Environnement et principes Grasshopper | D34: Écosystème de plugins | E34: Plugins d'ergonomie – principe | F34: Customisation de l’interface avec des plugins d’ergonomie ; | G34: Intermédiaire | H34: Programme de formation | M34: J2·S3 | O34: 1 | R34: Conceptuel (QCM) | S34: QCM / question ciblée | T34: P1
A35: 32 | B35: PRG-066 | C35: 1 – Environnement et principes Grasshopper | D35: Écosystème de plugins | E35: Plugin Bifocals | F35: Bifocals : Ajoute des étiquettes flottantes au-dessus des composants pour rendre l'interface plus lisible. | G35: Intermédiaire | H35: Programme de formation | M35: J2·S3 | O35: 1 | R35: Conceptuel (QCM) | S35: Démonstration formateur | T35: P1
A36: 33 | B36: PRG-067 | C36: 1 – Environnement et principes Grasshopper | D36: Écosystème de plugins | E36: Plugin SnappingGecko | F36: SnappingGecko : pour aimanter les composants les uns aux autres horizontalement ou verticalement, facilite le rangement | G36: Intermédiaire | H36: Programme de formation | M36: J2·S3 | O36: 1 | R36: Conceptuel (QCM) | S36: Démonstration formateur | T36: P1
A37: 34 | B37: PRG-068 | C37: 1 – Environnement et principes Grasshopper | D37: Écosystème de plugins | E37: Plugin Palette | F37: Palette : Changer les couleurs de l’interface Grasshopper | G37: Intermédiaire | H37: Programme de formation | M37: J2·S3 | O37: 1 | R37: Conceptuel (QCM) | S37: Démonstration formateur | T37: P1
A38: 35 | B38: PRG-069 | C38: 1 – Environnement et principes Grasshopper | D38: Écosystème de plugins | E38: Plugin Moonlight | F38: Moonlight : Ajoute un mode sombre à l’interface | G38: Intermédiaire | H38: Programme de formation | M38: J2·S3 | O38: 1 | R38: Conceptuel (QCM) | S38: Démonstration formateur | T38: P1
A39: 36 | B39: PRG-070 | C39: 1 – Environnement et principes Grasshopper | D39: Écosystème de plugins | E39: Plugin pOd | F39: pOd : pour afficher la vue Rhino sur le canvas Grasshopper | G39: Intermédiaire | H39: Programme de formation | M39: J2·S3 | O39: 1 | R39: Conceptuel (QCM) | S39: Démonstration formateur | T39: P1
A40: 37 | B40: PRG-071 | C40: 1 – Environnement et principes Grasshopper | D40: Écosystème de plugins | E40: Plugin AutoGraph | F40: AutoGraph : pour ranger automatiquement la definition et “déméler les “fils” entre les composants | G40: Intermédiaire | H40: Programme de formation | M40: J2·S3 | O40: 1 | R40: Conceptuel (QCM) | S40: Démonstration formateur | T40: P1
A41: 38 | B41: PRG-072 | C41: 1 – Environnement et principes Grasshopper | D41: Écosystème de plugins | E41: Plugins fonctionnels – principe | F41: Plugins essentiels couramment utilisés pour ajouter des fonctions à Grasshopper : | G41: Intermédiaire | H41: Programme de formation | M41: J2·S3 | O41: 1 | R41: Conceptuel (QCM) | S41: QCM / question ciblée | T41: P1
A42: 39 | B42: PRG-073 | C42: 1 – Environnement et principes Grasshopper | D42: Écosystème de plugins | E42: Plugins fonctionnels essentiels | F42: Metahopper, Human, Elefront, Weaverbird, Pufferfish, LunchBox | G42: Intermédiaire | H42: Programme de formation | M42: J2·S3 | O42: 1 | R42: Conceptuel (QCM) | S42: QCM / question ciblée | T42: P1
A43: 40 | B43: FND-01 | C43: 2 – Données et logique | D43: Types et conversion implicite | E43: Types de base et conversion implicite | F43: Comportement d'un flux de données (Number, Integer, Text, Boolean, Point...) quand il est accepté implicitement par un composant attendant un autre type (ex : slider → integer). | G43: Débutant | H43: Fondamentaux V1 – hors programmes (à ajouter) | P43: 1 | R43: SingleValue | S43: Exercice Grasshopper | T43: P0 | Y43: Notion issue du tableau des fondamentaux Magpie V1. Aucun item de programme correspondant.
A44: 41 | B44: FND-02 | C44: 2 – Données et logique | D44: Types et conversion implicite | E44: Échec de conversion et valeurs invalides | F44: Ce qui se produit quand une conversion implicite échoue (texte non numérique vers un input numérique, etc.) : message d'erreur, valeur nulle, composant en échec. | G44: Intermédiaire | H44: Fondamentaux V1 – hors programmes (à ajouter) | P44: 2 | R44: SingleValue | S44: Exercice Grasshopper | T44: P1 | Y44: Notion issue du tableau des fondamentaux Magpie V1. Aucun item de programme correspondant.
A45: 42 | B45: FND-03 | C45: 2 – Données et logique | D45: Listes | E45: Item, liste et indexation (0-based) | F45: Différence entre un item unique et une liste, lecture d'un élément à un index donné (List Item), indexation négative. | G45: Débutant | H45: Fondamentaux V1 – couverte par les programmes | P45: 3 | Q45: PRG-017 | R45: SingleValue | S45: Exercice Grasshopper | T45: P0 | Y45: Notion issue du tableau des fondamentaux Magpie V1. Rapprochement programme : PRG-017
A46: 43 | B46: FND-04 | C46: 2 – Données et logique | D46: Listes | E46: Longueur et génération de séries | F46: Comptage d'une liste (List Length) et génération de séquences numériques (Series, Range). | G46: Débutant | H46: Fondamentaux V1 – couverture partielle | P46: 4 | Q46: PRG-017 | R46: ExactOrderedList | S46: Exercice Grasshopper | T46: P0 | Y46: Notion issue du tableau des fondamentaux Magpie V1. Rapprochement programme : PRG-017
A47: 44 | B47: FND-07 | C47: 2 – Données et logique | D47: Listes | E47: Tri (Sort List, Sort Text) | F47: Réordonnancement d'une liste selon une clé de tri, avec ou sans liste secondaire liée. | G47: Débutant | H47: Fondamentaux V1 – couverte par les programmes | P47: 7 | Q47: PRG-017 | R47: ExactOrderedList | S47: Exercice Grasshopper | T47: P0 | Y47: Notion issue du tableau des fondamentaux Magpie V1. Rapprochement programme : PRG-017
A48: 45 | B48: FND-08 | C48: 2 – Données et logique | D48: Listes | E48: Filtrage et suppression (Cull Pattern, Dispatch) | F48: Élimination ou séparation d'éléments d'une liste selon un motif booléen répétitif. | G48: Intermédiaire | H48: Fondamentaux V1 – couverture partielle | P48: 8 | Q48: PRG-017 | R48: SetEquality | S48: Exercice Grasshopper | T48: P1 | Y48: Notion issue du tableau des fondamentaux Magpie V1. Rapprochement programme : PRG-017
A49: 46 | B49: FND-09 | C49: 2 – Données et logique | D49: Listes | E49: Décalage et permutation (Shift List, Reverse List) | F49: Rotation, décalage circulaire et inversion de l'ordre des éléments d'une liste. | G49: Intermédiaire | H49: Fondamentaux V1 – couverture partielle | P49: 9 | Q49: PRG-017 | R49: ExactOrderedList | S49: Exercice Grasshopper | T49: P1 | Y49: Notion issue du tableau des fondamentaux Magpie V1. Rapprochement programme : PRG-017
A50: 47 | B50: PRG-017 | C50: 2 – Données et logique | D50: Listes | E50: Listes – traitement et tri | F50: Outils de traitement des Listes, fonctions de tri par ordre croissant et décroissant | G50: Débutant | H50: Programme de formation | I50: J3 | K50: J1·S1 | L50: J1·S1 | M50: J1·S1 | N50: J5 | O50: 5 | R50: ExactOrderedList | S50: Exercice Grasshopper | T50: P0
A51: 48 | B51: FND-11 | C51: 2 – Données et logique | D51: Arbres de données | E51: Branche et chemin (path) | F51: Structure d'un arbre de données : notion de branche, de chemin ({0;0;1}) et de correspondance avec une liste imbriquée. | G51: Intermédiaire | H51: Fondamentaux V1 – couverte par les programmes | P51: 11 | Q51: PRG-018 | R51: SingleValue | S51: Exercice Grasshopper | T51: P1 | Y51: Notion issue du tableau des fondamentaux Magpie V1. Rapprochement programme : PRG-018
A52: 49 | B52: FND-12 | C52: 2 – Données et logique | D52: Arbres de données | E52: Graft et Flatten | F52: Transformation d'une structure de données : éclatement d'une liste en branches individuelles (Graft) et aplatissement d'un arbre en une seule liste (Flatten). | G52: Intermédiaire | H52: Fondamentaux V1 – couverte par les programmes | P52: 12 | Q52: PRG-024 | R52: SetEquality | S52: Exercice Grasshopper | T52: P1 | Y52: Notion issue du tableau des fondamentaux Magpie V1. Rapprochement programme : PRG-024
...

Sheet Fondamentaux V1
A1: Tableau des fondamentaux Magpie V1 – reprise à l'identique (source J. CAROLUS) | H1: Fondamentaux Grasshopper – Ind. A – 25/08/2026
A3: Ordre de dépendance | B3: Catégorie | C3: Notion | D3: Description | E3: ValidationMode suggéré | F3: A réaliser par | G3: Statut | H3: Lien
A4: 1 | B4: Types | C4: Types de base et conversion implicite | D4: Comportement d'un flux de données (Number, Integer, Text, Boolean, Point...) quand il est accepté implicitement par un composant attendant un autre type (ex : slider → integer). | E4: SingleValue
A5: 2 | B5: Types | C5: Échec de conversion et valeurs invalides | D5: Ce qui se produit quand une conversion implicite échoue (texte non numérique vers un input numérique, etc.) : message d'erreur, valeur nulle, composant en échec. | E5: SingleValue
A6: 3 | B6: Listes | C6: Item, liste et indexation (0-based) | D6: Différence entre un item unique et une liste, lecture d'un élément à un index donné (List Item), indexation négative. | E6: SingleValue
A7: 4 | B7: Listes | C7: Longueur et génération de séries | D7: Comptage d'une liste (List Length) et génération de séquences numériques (Series, Range). | E7: ExactOrderedList
A8: 5 | B8: Comportements implicites | C8: Data Matching par défaut (shortest list) | D8: Comportement automatique de Grasshopper quand deux listes de tailles différentes entrent dans un même composant : troncature implicite sur la plus courte. | E8: ExactOrderedList
A9: 6 | B9: Comportements implicites | C9: Data Matching explicite (Longest List, Cross Reference) | D9: Bascule volontaire entre les modes de correspondance (clic droit sur le composant) et conséquences sur le résultat produit. | E9: ExactOrderedList
A10: 7 | B10: Listes | C10: Tri (Sort List, Sort Text) | D10: Réordonnancement d'une liste selon une clé de tri, avec ou sans liste secondaire liée. | E10: ExactOrderedList
A11: 8 | B11: Listes | C11: Filtrage et suppression (Cull Pattern, Dispatch) | D11: Élimination ou séparation d'éléments d'une liste selon un motif booléen répétitif. | E11: SetEquality
A12: 9 | B12: Listes | C12: Décalage et permutation (Shift List, Reverse List) | D12: Rotation, décalage circulaire et inversion de l'ordre des éléments d'une liste. | E12: ExactOrderedList
A13: 10 | B13: Comportements implicites | C13: Valeurs nulles / vides dans une liste | D13: Propagation silencieuse des valeurs null à travers les composants et impact sur les calculs en aval. | E13: SetEquality
A14: 11 | B14: Arbres | C14: Branche et chemin (path) | D14: Structure d'un arbre de données : notion de branche, de chemin ({0;0;1}) et de correspondance avec une liste imbriquée. | E14: SingleValue
A15: 12 | B15: Arbres | C15: Graft et Flatten | D15: Transformation d'une structure de données : éclatement d'une liste en branches individuelles (Graft) et aplatissement d'un arbre en une seule liste (Flatten). | E15: SetEquality
... A22: 19 | B22: Portes logiques | C22: Structure conditionnelle | D22: Utilisation d'une condition pour orienter un résultat ou filtrer une liste (If, Stream Filter, Dispatch piloté par condition). | E22: SetEquality
A24: Légende ValidationMode :
A25: ExactOrderedList — ordre des éléments compte
A26: SetEquality — ordre indifférent, ensemble attendu
A27: SingleValue — une valeur unique attendue
A28: NumericTolerance — valeur numérique avec marge d'erreur
A29: GeometryTolerance — comparaison géométrique avec tolérance

Sheet Contenu programmes
A1: Relevé exhaustif du contenu des programmes de formation (verbatim) | I1: Fondamentaux Grasshopper – Ind. A – 25/08/2026
A3: N° | B3: Code | C3: Programme | D3: Jour | E3: Session | F3: Rubrique | G3: Item (verbatim) | H3: ID référentiel | I3: Domaine | J3: Catégorie
A4: 1 | B4: D3 | C4: Grasshopper débutant 3 jours | D4: Jour 1 | F4: Principes de base de Grasshopper | G4: Introduction à la conception paramétrique avec Grasshopper (Principes de la programmation visuelle) | H4: PRG-001 | I4: 1 – Environnement et principes Grasshopper | J4: Principes et interface Grasshopper
A5: 2 | B5: D3 | C5: Grasshopper débutant 3 jours | D5: Jour 1 | F5: Principes de base de Grasshopper | G5: Interopérabilité entre Grasshopper et Rhino (Bake et Geometry Pipeline) | H5: PRG-002 | I5: 1 – Environnement et principes Grasshopper | J5: Principes et interface Grasshopper
A6: 3 | B6: D3 | C6: Grasshopper débutant 3 jours | D6: Jour 1 | F6: Principes de base de Grasshopper | G6: La logique de Grasshopper (Curseurs, données d’entrée, panel, données de sortie, branchement des câbles… ) | H6: PRG-003 | I6: 1 – Environnement et principes Grasshopper | J6: Principes et interface Grasshopper
A7: 4 | B7: D3 | C7: Grasshopper débutant 3 jours | D7: Jour 1 | F7: Principes de base de Grasshopper | G7: L’environnement et l’interface de Grasshopper (Barre d’outils et navigation dans le Canvas) | H7: PRG-004 | I7: 1 – Environnement et principes Grasshopper | J7: Principes et interface Grasshopper
A8: 5 | B8: D3 | C8: Grasshopper débutant 3 jours | D8: Jour 1 | F8: Géométrie vectorielle et filaire sous Grasshopper | G8: Création d’éléments de construction vectoriels (Points, vecteurs, plans) | H8: PRG-005 | I8: 3 – Géométrie paramétrique | J8: Géométrie vectorielle et filaire
A9: 6 | B9: D3 | C9: Grasshopper débutant 3 jours | D9: Jour 1 | F9: Géométrie vectorielle et filaire sous Grasshopper | G9: Création de géométrie filaire (Cercles, carrés, Polygones, Courbes…) | H9: PRG-006 | I9: 3 – Géométrie paramétrique | J9: Géométrie vectorielle et filaire
A10: 7 | B10: D3 | C10: Grasshopper débutant 3 jours | D10: Jour 1 | F10: Géométrie vectorielle et filaire sous Grasshopper | G10: Les outils de division de courbes | H10: PRG-007 | I10: 3 – Géométrie paramétrique | J10: Géométrie vectorielle et filaire
A11: 8 | B11: D3 | C11: Grasshopper débutant 3 jours | D11: Jour 1 | F11: Plan paramétrique | G11: Exercice d’application sur un dessin paramétrique 2D | H11: PRG-008 | I11: 3 – Géométrie paramétrique | J11: Plan paramétrique
A12: 9 | B12: D3 | C12: Grasshopper débutant 3 jours | D12: Jour 1 | F12: Plan paramétrique | G12: Génération des cotations automatique | H12: PRG-009 | I12: 3 – Géométrie paramétrique | J12: Plan paramétrique
A13: 10 | B13: D3 | C13: Grasshopper débutant 3 jours | D13: Jour 2 | F13: Déplacement et de copie d’objets sous Grasshopper | G13: Les outils de transformation (matrice linéaire, polaire, rotation , symétrie…) | H13: PRG-010 | I13: 3 – Géométrie paramétrique | J13: Transformations et réseaux
A14: 11 | B14: D3 | C14: Grasshopper débutant 3 jours | D14: Jour 2 | F14: Déplacement et de copie d’objets sous Grasshopper | G14: Les matrices rectangulaires et polaires | H14: PRG-011 | I14: 3 – Géométrie paramétrique | J14: Transformations et réseaux
A15: 12 | B15: D3 | C15: Grasshopper débutant 3 jours | D15: Jour 2 | F15: Géométries surfaciques et solides sous Grasshopper | G15: Création de géométrie surfacique (balayage, surface par section…) | H15: PRG-012 | I15: 3 – Géométrie paramétrique | J15: Surfaces et solides
... A38: 35 | B38: P3 | C38: Grasshopper perfectionnement 3 jours | D38: Jour 3 | F38: Codage / programmation | G38: Ecrire un composant VB / C# / Python personnalisé dans grasshopper | H38: PRG-035 | I38: 7 – Développement, scripting et API | J38: Scripting dans Grasshopper
A39: 36 | B39: P6 | C39: Grasshopper perfectionnement 6 jours | D39: Jour 1 | E39: Session N°1 | F39: Gestion des données : utilisation fine des listes et des arbres de données | G39: Outils de traitement des Listes, fonctions de tri par ordre croissant et décroissant | H39: PRG-017 | I39: 2 – Données et logique | J39: Listes
A40: 37 | B40: P6 | C40: Grasshopper perfectionnement 6 jours | D40: Jour 1 | E40: Session N°1 | F40: Gestion des données : utilisation fine des listes et des arbres de données | G40: Création et lecture d’un arbre de données et numérotation des branches | H40: PRG-018 | I40: 2 – Données et logique | J40: Arbres de données
A41: 38 | B41: P6 | C41: Grasshopper perfectionnement 6 jours | D41: Jour 1 | E41: Session N°1 | F41: Gestion des données : utilisation fine des listes et des arbres de données | G41: Approfondir les listes et arbres de données (créer un arbre de données, lire dans un arbre de données, Graft et Flatten) | H41: PRG-024 | I41: 2 – Données et logique | J41: Arbres de données
A42: 39 | B42: P6 | C42: Grasshopper perfectionnement 6 jours | D42: Jour 1 | E42: Session N°1 | F42: Mesures | G42: Outils de mesure (Longueurs, Aires, Volumes) | H42: PRG-019 | I42: 4 – Mesures, quantitatifs et export | J42: Mesures géométriques
A43: 40 | B43: P6 | C43: Grasshopper perfectionnement 6 jours | D43: Jour 1 | E43: Session N°1 | F43: Mesures | G43: Mesure de rayon et courbure | H43: PRG-020 | I43: 4 – Mesures, quantitatifs et export | J43: Mesures géométriques
A44: 41 | B44: P6 | C44: Grasshopper perfectionnement 6 jours | D44: Jour 1 | E44: Session N°1 | F44: Mesures | G44: Recherche d’un centre de gravité | H44: PRG-021 | I44: 4 – Mesures, quantitatifs et export | J44: Mesures géométriques
A45: 42 | B45: P6 | C45: Grasshopper perfectionnement 6 jours | D45: Jour 1 | E45: Session N°1 | F45: Mesures | G45: Comptage automatique des quantités de blocs | H45: PRG-036 | I45: 4 – Mesures, quantitatifs et export | J45: Quantitatifs et chiffrage
A46: 43 | B46: P6 | C46: Grasshopper perfectionnement 6 jours | D46: Jour 1 | E46: Session N°2 | F46: Métrés et chiffrage | G46: Exercice d’application sur un calcul de métrés | H46: PRG-022 | I46: 4 – Mesures, quantitatifs et export | J46: Quantitatifs et chiffrage
A47: 44 | B47: P6 | C47: Grasshopper perfectionnement 6 jours | D47: Jour 1 | E47: Session N°2 | F47: Métrés et chiffrage | G47: Exercice d’application sur un devis généré à partir d’un modèle 3D grasshopper | H47: PRG-023 | I47: 4 – Mesures, quantitatifs et export | J47: Quantitatifs et chiffrage
A48: 45 | B48: P6 | C48: Grasshopper perfectionnement 6 jours | D48: Jour 1 | E48: Session N°2 | F48: Export EXCEL | G48: Préparation des données des colonnes dans Grasshopper | H48: PRG-037 | I48: 4 – Mesures, quantitatifs et export | J48: Export de données
A49: 46 | B49: P6 | C49: Grasshopper perfectionnement 6 jours | D49: Jour 1 | E49: Session N°2 | F49: Export EXCEL | G49: Export d’un tableau de données vers EXCEL dans une feuille de calcul | H49: PRG-038 | I49: 4 – Mesures, quantitatifs et export | J49: Export de données
A50: 47 | B50: P6 | C50: Grasshopper perfectionnement 6 jours | D50: Jour 1 | E50: Session N°2 | F50: Export EXCEL | G50: Export d’une nomenclature au format CSV à partir de Grasshopper | H50: PRG-039 | I50: 4 – Mesures, quantitatifs et export | J50: Export de données
... A178: 175 | B178: P6A | C178: Grasshopper perfectionnement 6 jours – Ind A – 27/02/2025 | D178: Jour 6 | E178: Session N°12 | F178: Déroulé automatique de pièce | G178: Déroulé de tôles en prenant en compte l’épaisseur de la pièce et le retrait | H178: PRG-062 | I178: 9 – Aide à la fabrication | J178: Déroulé et mise à plat
A179: 176 | B179: RG8 | C179: Rhino – Grasshopper 8 jours | D179: Jour 1 | F179: Les Fondamentaux de Rhino | G179: Présentation de l'interface utilisateur (barres d’outils, fenêtres, options). | H179: PRG-074 | I179: 0 – Socle Rhino (prérequis) | J179: Interface et navigation Rhino
A180: 177 | B180: RG8 | C180: Rhino – Grasshopper 8 jours | D180: Jour 1 | F180: Les Fondamentaux de Rhino | G180: Manipulation des vues | H180: PRG-075 | I180: 0 – Socle Rhino (prérequis) | J180: Interface et navigation Rhino
A181: 178 | B181: RG8 | C181: Rhino – Grasshopper 8 jours | D181: Jour 1 | F181: Les Fondamentaux de Rhino | G181: Outils de navigation : zoom, panoramique, rotation. | H181: PRG-076 | I181: 0 – Socle Rhino (prérequis) | J181: Interface et navigation Rhino
A182: 179 | B182: RG8 | C182: Rhino – Grasshopper 8 jours | D182: Jour 1 | F182: Les Fondamentaux de Rhino | G182: Création et manipulation d'objets de base (cubes, sphères, cylindres, etc.). | H182: PRG-077 | I182: 0 – Socle Rhino (prérequis) | J182: Modélisation Rhino
A183: 180 | B183: RG8 | C183: Rhino – Grasshopper 8 jours | D183: Jour 1 | F183: Les Fondamentaux de Rhino | G183: Transformation de base : déplacer, tourner, échelle, orienter | H183: PRG-078 | I183: 0 – Socle Rhino (prérequis) | J183: Modélisation Rhino
A184: 181 | B184: RG8 | C184: Rhino – Grasshopper 8 jours | D184: Jour 1 | F184: Les Fondamentaux de Rhino | G184: Sélection et manipulation d’objets | H184: PRG-079 | I184: 0 – Socle Rhino (prérequis) | J184: Interface et navigation Rhino
A185: 182 | B185: RG8 | C185: Rhino – Grasshopper 8 jours | D185: Jour 1 | F185: Les Fondamentaux de Rhino | G185: Groupes et blocs | H185: PRG-080 | I185: 0 – Socle Rhino (prérequis) | J185: Interface et navigation Rhino
A186: 183 | B186: RG8 | C186: Rhino – Grasshopper 8 jours | D186: Jour 1 | F186: Les Fondamentaux de Rhino | G186: Verrouillage et masquage d’objets, Isoler, Montrer) | H186: PRG-081 | I186: 0 – Socle Rhino (prérequis) | J186: Interface et navigation Rhino
A187: 184 | B187: RG8 | C187: Rhino – Grasshopper 8 jours | D187: Jour 1 | F187: Les Fondamentaux de Rhino | G187: Création de courbes de différentes formes (lignes, cercles, ellipses, etc.). | H187: PRG-082 | I187: 0 – Socle Rhino (prérequis) | J187: Modélisation Rhino
A188: 185 | B188: RG8 | C188: Rhino – Grasshopper 8 jours | D188: Jour 1 | F188: Les Fondamentaux de Rhino | G188: Utilisation de l’outil de courbes pour générer des surfaces. | H188: PRG-083 | I188: 0 – Socle Rhino (prérequis) | J188: Modélisation Rhino
A189: 186 | B189: RG8 | C189: Rhino – Grasshopper 8 jours | D189: Jour 1 | F189: Les Fondamentaux de Rhino | G189: Extrusion et création de surfaces à partir de courbes. | H189: PRG-084 | I189: 0 – Socle Rhino (prérequis) | J189: Modélisation Rhino
A190: 187 | B190: RG8 | C190: Rhino – Grasshopper 8 jours | D190: Jour 1 | F190: Les Fondamentaux de Rhino | G190: Opérations booléennes (Union, intersection, et soustraction) | H190: PRG-085 | I190: 0 – Socle Rhino (prérequis) | J190: Modélisation Rhino
...

Sheet Synthèse
A1: Synthèse et analyse des écarts | F1: Fondamentaux Grasshopper – Ind. A – 25/08/2026
A3: Répartition par domaine
A4: Domaine | B4: Notions | C4: dont issues des programmes | D4: dont priorité P0
A5: 0 – Socle Rhino (prérequis) | B5: =COUNTIF(Référentiel!$C$4:$C$119,$A5) -> 24 | C5: =COUNTIFS(Référentiel!$C$4:$C$119,$A5,Référentiel!$H$4:$H$119,"Programme de formation") -> 24 | D5: =COUNTIFS(Référentiel!$C$4:$C$119,$A5,Référentiel!$S$4:$S$119,"P0") -> 0
A6: 1 – Environnement et principes Grasshopper | B6: =COUNTIF(Référentiel!$C$4:$C$119,$A6) -> 15 | C6: =COUNTIFS(Référentiel!$C$4:$C$119,$A6,Référentiel!$H$4:$H$119,"Programme de formation") -> 15 | D6: =COUNTIFS(Référentiel!$C$4:$C$119,$A6,Référentiel!$S$4:$S$119,"P0") -> 0
A7: 2 – Données et logique | B7: =COUNTIF(Référentiel!$C$4:$C$119,$A7) -> 22 | C7: =COUNTIFS(Référentiel!$C$4:$C$119,$A7,Référentiel!$H$4:$H$119,"Programme de formation") -> 3 | D7: =COUNTIFS(Référentiel!$C$4:$C$119,$A7,Référentiel!$S$4:$S$119,"P0") -> 0
A8: 3 – Géométrie paramétrique | B8: =COUNTIF(Référentiel!$C$4:$C$119,$A8) -> 17 | C8: =COUNTIFS(Référentiel!$C$4:$C$119,$A8,Référentiel!$H$4:$H$119,"Programme de formation") -> 17 | D8: =COUNTIFS(Référentiel!$C$4:$C$119,$A8,Référentiel!$S$4:$S$119,"P0") -> 0
A9: 4 – Mesures, quantitatifs et export | B9: =COUNTIF(Référentiel!$C$4:$C$119,$A9) -> 9 | C9: =COUNTIFS(Référentiel!$C$4:$C$119,$A9,Référentiel!$H$4:$H$119,"Programme de formation") -> 9 | D9: =COUNTIFS(Référentiel!$C$4:$C$119,$A9,Référentiel!$S$4:$S$119,"P0") -> 0
A10: 5 – Méthode, performance et évènements | B10: =COUNTIF(Référentiel!$C$4:$C$119,$A10) -> 5 | C10: =COUNTIFS(Référentiel!$C$4:$C$119,$A10,Référentiel!$H$4:$H$119,"Programme de formation") -> 5 | D10: =COUNTIFS(Référentiel!$C$4:$C$119,$A10,Référentiel!$S$4:$S$119,"P0") -> 0
A11: 6 – Algorithmique avancée | B11: =COUNTIF(Référentiel!$C$4:$C$119,$A11) -> 3 | C11: =COUNTIFS(Référentiel!$C$4:$C$119,$A11,Référentiel!$H$4:$H$119,"Programme de formation") -> 3 | D11: =COUNTIFS(Référentiel!$C$4:$C$119,$A11,Référentiel!$S$4:$S$119,"P0") -> 0
A12: 7 – Développement, scripting et API | B12: =COUNTIF(Référentiel!$C$4:$C$119,$A12) -> 10 | C12: =COUNTIFS(Référentiel!$C$4:$C$119,$A12,Référentiel!$H$4:$H$119,"Programme de formation") -> 10 | D12: =COUNTIFS(Référentiel!$C$4:$C$119,$A12,Référentiel!$S$4:$S$119,"P0") -> 0
A13: 8 – Interfaces, web et interopérabilité | B13: =COUNTIF(Référentiel!$C$4:$C$119,$A13) -> 7 | C13: =COUNTIFS(Référentiel!$C$4:$C$119,$A13,Référentiel!$H$4:$H$119,"Programme de formation") -> 7 | D13: =COUNTIFS(Référentiel!$C$4:$C$119,$A13,Référentiel!$S$4:$S$119,"P0") -> 0
A14: 9 – Aide à la fabrication | B14: =COUNTIF(Référentiel!$C$4:$C$119,$A14) -> 4 | C14: =COUNTIFS(Référentiel!$C$4:$C$119,$A14,Référentiel!$H$4:$H$119,"Programme de formation") -> 4 | D14: =COUNTIFS(Référentiel!$C$4:$C$119,$A14,Référentiel!$S$4:$S$119,"P0") -> 0
A16: Répartition par niveau
A17: Niveau | B17: Notions
A18: Débutant | B18: =COUNTIF(Référentiel!$G$4:$G$119,$A18) -> 50
A19: Intermédiaire | B19: =COUNTIF(Référentiel!$G$4:$G$119,$A19) -> 33
A20: Perfectionnement | B20: =COUNTIF(Référentiel!$G$4:$G$119,$A20) -> 21
A21: Expert | B21: =COUNTIF(Référentiel!$G$4:$G$119,$A21) -> 12
A23: Répartition par mode de validation
A24: ValidationMode | B24: Notions
A25: ExactOrderedList | B25: =COUNTIF(Référentiel!$R$4:$R$119,$A25) -> 8
A26: SetEquality | B26: =COUNTIF(Référentiel!$R$4:$R$119,$A26) -> 9
A27: SingleValue | B27: =COUNTIF(Référentiel!$R$4:$R$119,$A27) -> 18
A28: NumericTolerance | B28: =COUNTIF(Référentiel!$R$4:$R$119,$A28) -> 8
A29: GeometryTolerance | B29: =COUNTIF(Référentiel!$R$4:$R$119,$A29) -> 26
A30: Conceptuel (QCM) | B30: =COUNTIF(Référentiel!$R$4:$R$119,$A30) -> 46
A32: Répartition par type d'exercice
A33: Type d'exercice | B33: Notions
A34: Exercice Grasshopper | B34: =COUNTIF(Référentiel!$S$4:$S$119,$A34) -> 66
A35: Exercice de synthèse | B35: =COUNTIF(Référentiel!$S$4:$S$119,$A35) -> 4
A36: QCM / question ciblée | B36: =COUNTIF(Référentiel!$S$4:$S$119,$A36) -> 22
A37: Démonstration formateur | B37: =COUNTIF(Référentiel!$S$4:$S$119,$A37) -> 24
A39: Couverture par programme
A40: Programme | B40: Items relevés (verbatim) | C40: Notions distinctes
A41: Grasshopper débutant 3 jours | B41: 23 | C41: =COUNTIF(Référentiel!$I$4:$I$119,"<>") -> 23
A42: Grasshopper perfectionnement 3 jours | B42: 12 | C42: =COUNTIF(Référentiel!$J$4:$J$119,"<>") -> 12
A43: Grasshopper perfectionnement 6 jours | B43: 43 | C43: =COUNTIF(Référentiel!$K$4:$K$119,"<>") -> 43
A44: Grasshopper perfectionnement 6 jours (1) | B44: 43 | C44: =COUNTIF(Référentiel!$L$4:$L$119,"<>") -> 43
A45: Grasshopper perfectionnement 6 jours – Ind A – 27/02/2025 | B45: 54 | C45: =COUNTIF(Référentiel!$M$4:$M$119,"<>") -> 54
...

Sheet Listes
A1: Listes de valeurs | F1: Fondamentaux Grasshopper – Ind. A – 25/08/2026
A3: Domaines | B3: Niveaux | C3: ValidationMode | D3: Types d'exercice | E3: Priorités | F3: Statuts
A4: 0 – Socle Rhino (prérequis) | B4: Débutant | C4: ExactOrderedList | D4: Exercice Grasshopper | E4: P0 | F4: Pas commencé
A5: 1 – Environnement et principes Grasshopper | B5: Intermédiaire | C5: SetEquality | D5: Exercice de synthèse | E5: P1 | F5: En cours
A6: 2 – Données et logique | B6: Perfectionnement | C6: SingleValue | D6: QCM / question ciblée | E6: P2 | F6: Terminé
A7: 3 – Géométrie paramétrique | B7: Expert | C7: NumericTolerance | D7: Démonstration formateur | F7: Bloqué
A8: 4 – Mesures, quantitatifs et export | C8: GeometryTolerance
A9: 5 – Méthode, performance et évènements | C9: Conceptuel (QCM)
A10: 6 – Algorithmique avancée
A11: 7 – Développement, scripting et API
A12: 8 – Interfaces, web et interopérabilité
A13: 9 – Aide à la fabrication
