Workbook

Sheet Lisez-moi
A1: Fondamentaux Grasshopper – Référentiel unifié des notions Magpie | D1: Fondamentaux Grasshopper – Ind. B – 26/08/2026
A3: Projet | B3: MAGPIE – outil d'exercices Grasshopper autocorrigés (RhinoForYou)
A4: Objet du document | B4: Référentiel unique des notions Rhino / Grasshopper à couvrir par les exercices Magpie.
A5: Indice | B5: Ind. B
A6: Date | B6: 26/08/2026
A7: Établi par | B7: Charles THIERRY DE VILLE D'AVRAY
A9: CE QUI CHANGE PAR RAPPORT À L'INDICE A
A10: Référentiel unifié | B10: Les 142 notions forment désormais un ensemble homogène. Plus aucune colonne, ni aucun identifiant, ne distingue les notions selon leur provenance.
A11: Identifiants | B11: REF-001 à REF-142, attribués dans l'ordre de lecture.
A12: Onglet supprimé | B12: « Fondamentaux V1 » : son contenu est fondu dans le référentiel.
A13: Colonnes supprimées | B13: Origine / couverture, D3, P3, P6, P6b, P6A, RG8, Nb prog., Ordre V1, Réf. croisée.
A15: CONTENU DU CLASSEUR
A16: Référentiel | B16: 142 notions, classées par domaine puis par catégorie.
A17: Contenu programmes | B17: Relevé verbatim des items des programmes de formation, rattachés à une ligne du référentiel. Conservé comme pièce justificative des sources.
A18: Synthèse | B18: Comptages par domaine, niveau, mode de validation et type d'exercice.
A19: Listes | B19: Listes de valeurs des menus déroulants du référentiel.
A21: LÉGENDE — MODE DE VALIDATION
A22: ExactOrderedList | B22: Ordre des éléments significatif.
A23: SetEquality | B23: Ordre indifférent, ensemble attendu.
A24: SingleValue | B24: Une valeur unique attendue.
A25: NumericTolerance | B25: Valeur numérique avec marge d'erreur.
A26: GeometryTolerance | B26: Comparaison géométrique avec tolérance.
A27: Conceptuel (QCM) | B27: Notion non vérifiable par comparaison de résultat.
A29: POINT À ARBITRER
A30: Correspondance par défaut | B30: L'intitulé de la notion « Data Matching par défaut (shortest list) » est inexact : voir l'avertissement porté en colonne Notes de cette ligne.
A32: JOURNAL DES INDICES
A33: Indice | B33: Objet | C33: Date | D33: Auteur
A34: Ind. A | B34: Création. Fusion du tableau d'origine et du contenu des 6 programmes de formation, avec matrice de couverture et analyse des écarts. | C34: 25/08/2026 | D34: C. THIERRY DE VILLE D'AVRAY
A35: Ind. B | B35: Unification. Suppression de l'onglet « Fondamentaux V1 », des colonnes de provenance et de couverture, et des préfixes d'identifiant. Identifiants renumérotés REF-001 à REF-142. | C35: 26/08/2026 | D35: C. THIERRY DE VILLE D'AVRAY

Sheet Référentiel
A1: Référentiel des notions – Rhino / Grasshopper | Q1: Fondamentaux Grasshopper – Ind. B – 26/08/2026
A3: N° | B3: ID | C3: Domaine | D3: Catégorie | E3: Notion | F3: Description | G3: Niveau | H3: ValidationMode suggéré | I3: Type d'exercice | J3: Priorité de production | K3: Nb exercices Magpie prévus | L3: À réaliser par | M3: Statut | N3: Lien | O3: Notes | P3: Nature pédagogique | Q3: Exercices Magpie
A4: 1 | B4: REF-001 | C4: 1 – Socle Rhino (prérequis) | D4: Interface et navigation Rhino | E4: Interface Rhino | F4: Présentation de l'interface utilisateur (barres d’outils, fenêtres, options). | G4: Débutant | H4: Conceptuel (QCM) | I4: QCM / question ciblée | J4: P0 | P4: Compétence | Q4: RH-01, RH-11
A5: 2 | B5: REF-002 | C5: 1 – Socle Rhino (prérequis) | D5: Interface et navigation Rhino | E5: Manipulation des vues | F5: Manipulation des vues | G5: Débutant | H5: Conceptuel (QCM) | I5: QCM / question ciblée | J5: P0 | P5: Compétence | Q5: RH-01, RH-11, RH-12
A6: 3 | B6: REF-003 | C6: 1 – Socle Rhino (prérequis) | D6: Interface et navigation Rhino | E6: Navigation | F6: Outils de navigation : zoom, panoramique, rotation. | G6: Débutant | H6: Conceptuel (QCM) | I6: QCM / question ciblée | J6: P0 | P6: Compétence | Q6: RH-01, RH-11
A7: 4 | B7: REF-004 | C7: 1 – Socle Rhino (prérequis) | D7: Interface et navigation Rhino | E7: Sélection d'objets | F7: Sélection et manipulation d’objets | G7: Débutant | H7: Conceptuel (QCM) | I7: QCM / question ciblée | J7: P0 | P7: Compétence | Q7: RH-02, RH-13
A8: 5 | B8: REF-005 | C8: 1 – Socle Rhino (prérequis) | D8: Interface et navigation Rhino | E8: Groupes et blocs | F8: Groupes et blocs | G8: Débutant | H8: Conceptuel (QCM) | I8: QCM / question ciblée | J8: P0 | P8: Connaissance | Q8: RH-06
A9: 6 | B9: REF-006 | C9: 1 – Socle Rhino (prérequis) | D9: Interface et navigation Rhino | E9: Visibilité des objets | F9: Verrouillage et masquage d’objets, Isoler, Montrer) | G9: Débutant | H9: Conceptuel (QCM) | I9: QCM / question ciblée | J9: P0 | P9: Compétence | Q9: RH-02, RH-13
A10: 7 | B10: REF-007 | C10: 1 – Socle Rhino (prérequis) | D10: Modélisation Rhino | E10: Objets de base | F10: Création et manipulation d'objets de base (cubes, sphères, cylindres, etc.). | G10: Débutant | H10: GeometryTolerance | I10: Exercice Grasshopper | J10: P0 | P10: Compétence | Q10: RH-03
A11: 8 | B11: REF-008 | C11: 1 – Socle Rhino (prérequis) | D11: Modélisation Rhino | E11: Transformations de base | F11: Transformation de base : déplacer, tourner, échelle, orienter | G11: Débutant | H11: GeometryTolerance | I11: Exercice Grasshopper | J11: P0 | P11: Compétence | Q11: RH-03, RH-14
A12: 9 | B12: REF-009 | C12: 1 – Socle Rhino (prérequis) | D12: Modélisation Rhino | E12: Courbes Rhino | F12: Création de courbes de différentes formes (lignes, cercles, ellipses, etc.). | G12: Débutant | H12: GeometryTolerance | I12: Exercice Grasshopper | J12: P0 | P12: Compétence | Q12: RH-04, RH-15
A13: 10 | B13: REF-010 | C13: 1 – Socle Rhino (prérequis) | D13: Modélisation Rhino | E13: Surfaces depuis courbes | F13: Utilisation de l’outil de courbes pour générer des surfaces. | G13: Débutant | H13: GeometryTolerance | I13: Exercice Grasshopper | J13: P0 | P13: Compétence | Q13: RH-04, RH-16
A14: 11 | B14: REF-011 | C14: 1 – Socle Rhino (prérequis) | D14: Modélisation Rhino | E14: Extrusion | F14: Extrusion et création de surfaces à partir de courbes. | G14: Débutant | H14: GeometryTolerance | I14: Exercice Grasshopper | J14: P0 | P14: Compétence | Q14: RH-04, RH-16
A15: 12 | B15: REF-012 | C15: 1 – Socle Rhino (prérequis) | D15: Modélisation Rhino | E15: Opérations booléennes Rhino | F15: Opérations booléennes (Union, intersection, et soustraction) | G15: Débutant | H15: GeometryTolerance | I15: Exercice Grasshopper | J15: P0 | P15: Compétence | Q15: RH-05, RH-17
... A55: 52 | B55: REF-052 | C55: 3 – Données et logique | D55: Arbres de données | E55: Arbres – Graft et Flatten | F55: Approfondir les listes et arbres de données (créer un arbre de données, lire dans un arbre de données, Graft et Flatten) | G55: Intermédiaire | H55: SetEquality | I55: Exercice Grasshopper | J55: P1 | P55: Compétence | Q55: A-20
A56: 53 | B56: REF-053 | C56: 3 – Données et logique | D56: Comportements implicites | E56: Data Matching par défaut (shortest list) | F56: Comportement automatique de Grasshopper quand deux listes de tailles différentes entrent dans un même composant : troncature implicite sur la plus courte. | G56: Intermédiaire | H56: ExactOrderedList | I56: Exercice Grasshopper | J56: P1 | O56: ⚠ Vérifié dans Rhino 8 le 26/08/2026 : la correspondance PAR DÉFAUT de Grasshopper n'est pas la troncature sur la liste la plus courte, mais la correspondance sur la liste la plus LONGUE, la liste courte étant prolongée par répétition de son dernier élément. Une liste de 10 et une liste de 4 dans une Addition produisent 10 résultats, pas 4. Le mode Shortest List existe mais doit être demandé explicitement par clic droit. L'intitulé de cette notion est donc à corriger. | P56: Connaissance | Q56: A-24
A57: 54 | B57: REF-054 | C57: 3 – Données et logique | D57: Comportements implicites | E57: Data Matching explicite (Longest List, Cross Reference) | F57: Bascule volontaire entre les modes de correspondance (clic droit sur le composant) et conséquences sur le résultat produit. | G57: Intermédiaire | H57: ExactOrderedList | I57: Exercice Grasshopper | J57: P1 | P57: Compétence | Q57: A-25
A58: 55 | B58: REF-055 | C58: 3 – Données et logique | D58: Comportements implicites | E58: Valeurs nulles / vides dans une liste | F58: Propagation silencieuse des valeurs null à travers les composants et impact sur les calculs en aval. | G58: Intermédiaire | H58: SetEquality | I58: Exercice Grasshopper | J58: P1 | P58: Compétence | Q58: A-09
A59: 56 | B59: REF-056 | C59: 3 – Données et logique | D59: Comportements implicites | E59: Recalcul automatique et ordre d'évaluation | F59: Logique de mise à jour du canvas : recalcul en cascade à la modification d'une entrée, notion de dépendance entre composants (conceptuel, à valider via question ciblée plutôt que comparaison de résultat). | G59: Intermédiaire | H59: SingleValue (conceptuel) | I59: Exercice Grasshopper | J59: P1 | P59: Connaissance | Q59: A-26
A60: 57 | B60: REF-057 | C60: 3 – Données et logique | D60: Outils de texte | E60: Concaténation et construction de chaînes | F60: Assemblage de plusieurs éléments en une seule chaîne de caractères (Concatenate, Text Join) avec ou sans séparateur. | G60: Débutant | H60: SingleValue | I60: Exercice Grasshopper | J60: P0 | P60: Compétence | Q60: A-27
A61: 58 | B61: REF-058 | C61: 3 – Données et logique | D61: Outils de texte | E61: Manipulation de texte | F61: Opérations courantes sur une chaîne : découpe (Split), remplacement (Replace), nettoyage (Trim), casse (Upper/Lower). | G61: Intermédiaire | H61: SingleValue | I61: Exercice Grasshopper | J61: P1 | P61: Compétence | Q61: A-28
A62: 59 | B62: REF-059 | C62: 3 – Données et logique | D62: Portes logiques | E62: Booléens et comparaisons | F62: Production d'une valeur booléenne à partir d'une comparaison (Equality, Larger Than, Smaller Than). | G62: Débutant | H62: SingleValue | I62: Exercice Grasshopper | J62: P0 | P62: Compétence | Q62: A-08, A-29
A63: 60 | B63: REF-060 | C63: 3 – Données et logique | D63: Portes logiques | E63: Opérateurs logiques combinés | F63: Combinaison de plusieurs conditions (And, Or, Not, Logic Gate) pour produire un résultat booléen unique. | G63: Intermédiaire | H63: SingleValue | I63: Exercice Grasshopper | J63: P1 | P63: Compétence | Q63: A-30
A64: 61 | B64: REF-061 | C64: 3 – Données et logique | D64: Portes logiques | E64: Structure conditionnelle | F64: Utilisation d'une condition pour orienter un résultat ou filtrer une liste (If, Stream Filter, Dispatch piloté par condition). | G64: Intermédiaire | H64: SetEquality | I64: Exercice Grasshopper | J64: P1 | P64: Compétence | Q64: A-15, A-31
A65: 62 | B65: REF-062 | C65: 4 – Géométrie paramétrique | D65: Géométrie vectorielle et filaire | E65: Géométrie vectorielle | F65: Création d’éléments de construction vectoriels (Points, vecteurs, plans) | G65: Débutant | H65: GeometryTolerance | I65: Exercice Grasshopper | J65: P0 | P65: Compétence | Q65: A-02, A-32, A-33
A66: 63 | B66: REF-063 | C66: 4 – Géométrie paramétrique | D66: Géométrie vectorielle et filaire | E66: Géométrie filaire | F66: Création de géométrie filaire (Cercles, carrés, Polygones, Courbes…) | G66: Débutant | H66: GeometryTolerance | I66: Exercice Grasshopper | J66: P0 | P66: Compétence | Q66: A-34, A-36
A67: 64 | B67: REF-064 | C67: 4 – Géométrie paramétrique | D67: Géométrie vectorielle et filaire | E67: Division de courbes | F67: Les outils de division de courbes | G67: Débutant | H67: GeometryTolerance | I67: Exercice Grasshopper | J67: P0 | P67: Compétence | Q67: A-35
A68: 65 | B68: REF-065 | C68: 4 – Géométrie paramétrique | D68: Plan paramétrique | E68: Dessin paramétrique 2D | F68: Exercice d’application sur un dessin paramétrique 2D | G68: Débutant | H68: GeometryTolerance | I68: Exercice de synthèse | J68: P0 | P68: Compétence | Q68: GP-01, GP-05
... A145: 142 | B145: REF-142 | C145: 11 – IA et assistance générative | D145: Vérification, licences et limites | E145: Reproductibilité, coût et latence | F145: Mesurer ce que coûte un appel à un modèle dans une définition qui recalcule en continu, et pourquoi deux appels identiques peuvent différer. | G145: Perfectionnement | H145: Conceptuel (QCM) | I145: QCM / question ciblée | J145: P3 | P145: Compétence | Q145: IA-14, IA-25

Sheet Contenu programmes
A1: Relevé exhaustif du contenu des programmes de formation (verbatim) | J1: Fondamentaux Grasshopper – Ind. B – 26/08/2026
A3: N° | B3: Code | C3: Programme | D3: Jour | E3: Session | F3: Rubrique | G3: Item (verbatim) | H3: ID référentiel | I3: Domaine | J3: Catégorie
A4: 1 | B4: D3 | C4: Grasshopper débutant 3 jours | D4: Jour 1 | F4: Principes de base de Grasshopper | G4: Introduction à la conception paramétrique avec Grasshopper (Principes de la programmation visuelle) | H4: REF-025 | I4: 1 – Environnement et principes Grasshopper | J4: Principes et interface Grasshopper
A5: 2 | B5: D3 | C5: Grasshopper débutant 3 jours | D5: Jour 1 | F5: Principes de base de Grasshopper | G5: Interopérabilité entre Grasshopper et Rhino (Bake et Geometry Pipeline) | H5: REF-026 | I5: 1 – Environnement et principes Grasshopper | J5: Principes et interface Grasshopper
A6: 3 | B6: D3 | C6: Grasshopper débutant 3 jours | D6: Jour 1 | F6: Principes de base de Grasshopper | G6: La logique de Grasshopper (Curseurs, données d’entrée, panel, données de sortie, branchement des câbles… ) | H6: REF-027 | I6: 1 – Environnement et principes Grasshopper | J6: Principes et interface Grasshopper
A7: 4 | B7: D3 | C7: Grasshopper débutant 3 jours | D7: Jour 1 | F7: Principes de base de Grasshopper | G7: L’environnement et l’interface de Grasshopper (Barre d’outils et navigation dans le Canvas) | H7: REF-028 | I7: 1 – Environnement et principes Grasshopper | J7: Principes et interface Grasshopper
A8: 5 | B8: D3 | C8: Grasshopper débutant 3 jours | D8: Jour 1 | F8: Géométrie vectorielle et filaire sous Grasshopper | G8: Création d’éléments de construction vectoriels (Points, vecteurs, plans) | H8: REF-062 | I8: 3 – Géométrie paramétrique | J8: Géométrie vectorielle et filaire
A9: 6 | B9: D3 | C9: Grasshopper débutant 3 jours | D9: Jour 1 | F9: Géométrie vectorielle et filaire sous Grasshopper | G9: Création de géométrie filaire (Cercles, carrés, Polygones, Courbes…) | H9: REF-063 | I9: 3 – Géométrie paramétrique | J9: Géométrie vectorielle et filaire
A10: 7 | B10: D3 | C10: Grasshopper débutant 3 jours | D10: Jour 1 | F10: Géométrie vectorielle et filaire sous Grasshopper | G10: Les outils de division de courbes | H10: REF-064 | I10: 3 – Géométrie paramétrique | J10: Géométrie vectorielle et filaire
A11: 8 | B11: D3 | C11: Grasshopper débutant 3 jours | D11: Jour 1 | F11: Plan paramétrique | G11: Exercice d’application sur un dessin paramétrique 2D | H11: REF-065 | I11: 3 – Géométrie paramétrique | J11: Plan paramétrique
A12: 9 | B12: D3 | C12: Grasshopper débutant 3 jours | D12: Jour 1 | F12: Plan paramétrique | G12: Génération des cotations automatique | H12: REF-066 | I12: 3 – Géométrie paramétrique | J12: Plan paramétrique
A13: 10 | B13: D3 | C13: Grasshopper débutant 3 jours | D13: Jour 2 | F13: Déplacement et de copie d’objets sous Grasshopper | G13: Les outils de transformation (matrice linéaire, polaire, rotation , symétrie…) | H13: REF-067 | I13: 3 – Géométrie paramétrique | J13: Transformations et réseaux
A14: 11 | B14: D3 | C14: Grasshopper débutant 3 jours | D14: Jour 2 | F14: Déplacement et de copie d’objets sous Grasshopper | G14: Les matrices rectangulaires et polaires | H14: REF-068 | I14: 3 – Géométrie paramétrique | J14: Transformations et réseaux
A15: 12 | B15: D3 | C15: Grasshopper débutant 3 jours | D15: Jour 2 | F15: Géométries surfaciques et solides sous Grasshopper | G15: Création de géométrie surfacique (balayage, surface par section…) | H15: REF-069 | I15: 3 – Géométrie paramétrique | J15: Surfaces et solides
... A38: 35 | B38: P3 | C38: Grasshopper perfectionnement 3 jours | D38: Jour 3 | F38: Codage / programmation | G38: Ecrire un composant VB / C# / Python personnalisé dans grasshopper | H38: REF-100 | I38: 7 – Développement, scripting et API | J38: Scripting dans Grasshopper
A39: 36 | B39: P6 | C39: Grasshopper perfectionnement 6 jours | D39: Jour 1 | E39: Session N°1 | F39: Gestion des données : utilisation fine des listes et des arbres de données | G39: Outils de traitement des Listes, fonctions de tri par ordre croissant et décroissant | H39: REF-047 | I39: 2 – Données et logique | J39: Listes
A40: 37 | B40: P6 | C40: Grasshopper perfectionnement 6 jours | D40: Jour 1 | E40: Session N°1 | F40: Gestion des données : utilisation fine des listes et des arbres de données | G40: Création et lecture d’un arbre de données et numérotation des branches | H40: REF-051 | I40: 2 – Données et logique | J40: Arbres de données
A41: 38 | B41: P6 | C41: Grasshopper perfectionnement 6 jours | D41: Jour 1 | E41: Session N°1 | F41: Gestion des données : utilisation fine des listes et des arbres de données | G41: Approfondir les listes et arbres de données (créer un arbre de données, lire dans un arbre de données, Graft et Flatten) | H41: REF-052 | I41: 2 – Données et logique | J41: Arbres de données
A42: 39 | B42: P6 | C42: Grasshopper perfectionnement 6 jours | D42: Jour 1 | E42: Session N°1 | F42: Mesures | G42: Outils de mesure (Longueurs, Aires, Volumes) | H42: REF-079 | I42: 4 – Mesures, quantitatifs et export | J42: Mesures géométriques
A43: 40 | B43: P6 | C43: Grasshopper perfectionnement 6 jours | D43: Jour 1 | E43: Session N°1 | F43: Mesures | G43: Mesure de rayon et courbure | H43: REF-080 | I43: 4 – Mesures, quantitatifs et export | J43: Mesures géométriques
A44: 41 | B44: P6 | C44: Grasshopper perfectionnement 6 jours | D44: Jour 1 | E44: Session N°1 | F44: Mesures | G44: Recherche d’un centre de gravité | H44: REF-081 | I44: 4 – Mesures, quantitatifs et export | J44: Mesures géométriques
A45: 42 | B45: P6 | C45: Grasshopper perfectionnement 6 jours | D45: Jour 1 | E45: Session N°1 | F45: Mesures | G45: Comptage automatique des quantités de blocs | H45: REF-084 | I45: 4 – Mesures, quantitatifs et export | J45: Quantitatifs et chiffrage
A46: 43 | B46: P6 | C46: Grasshopper perfectionnement 6 jours | D46: Jour 1 | E46: Session N°2 | F46: Métrés et chiffrage | G46: Exercice d’application sur un calcul de métrés | H46: REF-082 | I46: 4 – Mesures, quantitatifs et export | J46: Quantitatifs et chiffrage
A47: 44 | B47: P6 | C47: Grasshopper perfectionnement 6 jours | D47: Jour 1 | E47: Session N°2 | F47: Métrés et chiffrage | G47: Exercice d’application sur un devis généré à partir d’un modèle 3D grasshopper | H47: REF-083 | I47: 4 – Mesures, quantitatifs et export | J47: Quantitatifs et chiffrage
A48: 45 | B48: P6 | C48: Grasshopper perfectionnement 6 jours | D48: Jour 1 | E48: Session N°2 | F48: Export EXCEL | G48: Préparation des données des colonnes dans Grasshopper | H48: REF-085 | I48: 4 – Mesures, quantitatifs et export | J48: Export de données
A49: 46 | B49: P6 | C49: Grasshopper perfectionnement 6 jours | D49: Jour 1 | E49: Session N°2 | F49: Export EXCEL | G49: Export d’un tableau de données vers EXCEL dans une feuille de calcul | H49: REF-086 | I49: 4 – Mesures, quantitatifs et export | J49: Export de données
A50: 47 | B50: P6 | C50: Grasshopper perfectionnement 6 jours | D50: Jour 1 | E50: Session N°2 | F50: Export EXCEL | G50: Export d’une nomenclature au format CSV à partir de Grasshopper | H50: REF-087 | I50: 4 – Mesures, quantitatifs et export | J50: Export de données
... A178: 175 | B178: P6A | C178: Grasshopper perfectionnement 6 jours – Ind A – 27/02/2025 | D178: Jour 6 | E178: Session N°12 | F178: Déroulé automatique de pièce | G178: Déroulé de tôles en prenant en compte l’épaisseur de la pièce et le retrait | H178: REF-116 | I178: 9 – Aide à la fabrication | J178: Déroulé et mise à plat
A179: 176 | B179: RG8 | C179: Rhino – Grasshopper 8 jours | D179: Jour 1 | F179: Les Fondamentaux de Rhino | G179: Présentation de l'interface utilisateur (barres d’outils, fenêtres, options). | H179: REF-001 | I179: 0 – Socle Rhino (prérequis) | J179: Interface et navigation Rhino
A180: 177 | B180: RG8 | C180: Rhino – Grasshopper 8 jours | D180: Jour 1 | F180: Les Fondamentaux de Rhino | G180: Manipulation des vues | H180: REF-002 | I180: 0 – Socle Rhino (prérequis) | J180: Interface et navigation Rhino
A181: 178 | B181: RG8 | C181: Rhino – Grasshopper 8 jours | D181: Jour 1 | F181: Les Fondamentaux de Rhino | G181: Outils de navigation : zoom, panoramique, rotation. | H181: REF-003 | I181: 0 – Socle Rhino (prérequis) | J181: Interface et navigation Rhino
A182: 179 | B182: RG8 | C182: Rhino – Grasshopper 8 jours | D182: Jour 1 | F182: Les Fondamentaux de Rhino | G182: Création et manipulation d'objets de base (cubes, sphères, cylindres, etc.). | H182: REF-007 | I182: 0 – Socle Rhino (prérequis) | J182: Modélisation Rhino
A183: 180 | B183: RG8 | C183: Rhino – Grasshopper 8 jours | D183: Jour 1 | F183: Les Fondamentaux de Rhino | G183: Transformation de base : déplacer, tourner, échelle, orienter | H183: REF-008 | I183: 0 – Socle Rhino (prérequis) | J183: Modélisation Rhino
A184: 181 | B184: RG8 | C184: Rhino – Grasshopper 8 jours | D184: Jour 1 | F184: Les Fondamentaux de Rhino | G184: Sélection et manipulation d’objets | H184: REF-004 | I184: 0 – Socle Rhino (prérequis) | J184: Interface et navigation Rhino
A185: 182 | B185: RG8 | C185: Rhino – Grasshopper 8 jours | D185: Jour 1 | F185: Les Fondamentaux de Rhino | G185: Groupes et blocs | H185: REF-005 | I185: 0 – Socle Rhino (prérequis) | J185: Interface et navigation Rhino
A186: 183 | B186: RG8 | C186: Rhino – Grasshopper 8 jours | D186: Jour 1 | F186: Les Fondamentaux de Rhino | G186: Verrouillage et masquage d’objets, Isoler, Montrer) | H186: REF-006 | I186: 0 – Socle Rhino (prérequis) | J186: Interface et navigation Rhino
A187: 184 | B187: RG8 | C187: Rhino – Grasshopper 8 jours | D187: Jour 1 | F187: Les Fondamentaux de Rhino | G187: Création de courbes de différentes formes (lignes, cercles, ellipses, etc.). | H187: REF-009 | I187: 0 – Socle Rhino (prérequis) | J187: Modélisation Rhino
A188: 185 | B188: RG8 | C188: Rhino – Grasshopper 8 jours | D188: Jour 1 | F188: Les Fondamentaux de Rhino | G188: Utilisation de l’outil de courbes pour générer des surfaces. | H188: REF-010 | I188: 0 – Socle Rhino (prérequis) | J188: Modélisation Rhino
A189: 186 | B189: RG8 | C189: Rhino – Grasshopper 8 jours | D189: Jour 1 | F189: Les Fondamentaux de Rhino | G189: Extrusion et création de surfaces à partir de courbes. | H189: REF-011 | I189: 0 – Socle Rhino (prérequis) | J189: Modélisation Rhino
A190: 187 | B190: RG8 | C190: Rhino – Grasshopper 8 jours | D190: Jour 1 | F190: Les Fondamentaux de Rhino | G190: Opérations booléennes (Union, intersection, et soustraction) | H190: REF-012 | I190: 0 – Socle Rhino (prérequis) | J190: Modélisation Rhino
...

Sheet Synthèse
A1: Synthèse | C1: Fondamentaux Grasshopper – Ind. B – 26/08/2026
A3: Répartition par domaine
A4: Domaine | B4: Nb notions
A5: 1 – Socle Rhino (prérequis) | B5: =COUNTIF(Référentiel!$C$4:$C$145,$A$5)
A6: 10 – Aide à la fabrication | B6: =COUNTIF(Référentiel!$C$4:$C$145,$A$6)
A7: 11 – IA et assistance générative | B7: =COUNTIF(Référentiel!$C$4:$C$145,$A$7)
A8: 2 – Environnement et principes Grasshopper | B8: =COUNTIF(Référentiel!$C$4:$C$145,$A$8)
A9: 3 – Données et logique | B9: =COUNTIF(Référentiel!$C$4:$C$145,$A$9)
A10: 4 – Géométrie paramétrique | B10: =COUNTIF(Référentiel!$C$4:$C$145,$A$10)
A11: 5 – Mesures, quantitatifs et export | B11: =COUNTIF(Référentiel!$C$4:$C$145,$A$11)
A12: 6 – Méthode, performance et évènements | B12: =COUNTIF(Référentiel!$C$4:$C$145,$A$12)
A13: 7 – Algorithmique avancée | B13: =COUNTIF(Référentiel!$C$4:$C$145,$A$13)
A14: 8 – Développement, scripting et API | B14: =COUNTIF(Référentiel!$C$4:$C$145,$A$14)
A15: 9 – Interfaces, web et interopérabilité | B15: =COUNTIF(Référentiel!$C$4:$C$145,$A$15)
A17: Répartition par niveau
A18: Niveau | B18: Nb notions
A19: Débutant | B19: =COUNTIF(Référentiel!$G$4:$G$145,$A$19)
A20: Intermédiaire | B20: =COUNTIF(Référentiel!$G$4:$G$145,$A$20)
A21: Perfectionnement | B21: =COUNTIF(Référentiel!$G$4:$G$145,$A$21)
A22: Expert | B22: =COUNTIF(Référentiel!$G$4:$G$145,$A$22)
A24: Répartition par mode de validation
A25: Mode de validation | B25: Nb notions
A26: ExactOrderedList | B26: =COUNTIF(Référentiel!$H$4:$H$145,$A$26)
A27: SetEquality | B27: =COUNTIF(Référentiel!$H$4:$H$145,$A$27)
A28: SingleValue | B28: =COUNTIF(Référentiel!$H$4:$H$145,$A$28)
A29: NumericTolerance | B29: =COUNTIF(Référentiel!$H$4:$H$145,$A$29)
A30: GeometryTolerance | B30: =COUNTIF(Référentiel!$H$4:$H$145,$A$30)
A31: Conceptuel (QCM) | B31: =COUNTIF(Référentiel!$H$4:$H$145,$A$31)
A33: Répartition par type d'exercice
A34: Type d'exercice | B34: Nb notions
A35: Exercice Grasshopper | B35: =COUNTIF(Référentiel!$I$4:$I$145,$A$35)
A36: Exercice de synthèse | B36: =COUNTIF(Référentiel!$I$4:$I$145,$A$36)
A37: QCM / question ciblée | B37: =COUNTIF(Référentiel!$I$4:$I$145,$A$37)
A38: Démonstration formateur | B38: =COUNTIF(Référentiel!$I$4:$I$145,$A$38)
A40: Total des notions | B40: 142

Sheet Listes
A1: Listes de valeurs | F1: Fondamentaux Grasshopper – Ind. B – 26/08/2026
A3: Domaines | B3: Niveaux | C3: ValidationMode | D3: Types d'exercice | E3: Priorités | F3: Statuts
A4: 0 – Socle Rhino (prérequis) | B4: Débutant | C4: ExactOrderedList | D4: Exercice Grasshopper | E4: P0 | F4: Pas commencé
A5: 1 – Environnement et principes Grasshopper | B5: Intermédiaire | C5: SetEquality | D5: Exercice de synthèse | E5: P1 | F5: En cours
A6: 2 – Données et logique | B6: Perfectionnement | C6: SingleValue | D6: QCM / question ciblée | E6: P2 | F6: Terminé
A7: 3 – Géométrie paramétrique | B7: Expert | C7: NumericTolerance | D7: Démonstration formateur | F7: Bloqué
A8: 4 – Mesures, quantitatifs et export | C8: GeometryTolerance
A9: 5 – Méthode, performance et évènements | C9: Conceptuel (QCM)
A10: 6 – Algorithmique avancée
A11: 7 – Développement, scripting et API
A12: 8 – Interfaces, web et interopérabilité
A13: 9 – Aide à la fabrication
